<?xml version="1.0"?>
<robot xmlns:xacro="http://ros.org/wiki/xacro">
  
  <!-- Define caster wheel macro -->
  <xacro:macro name="caster_wheel" params="wheel_name parent_link origin_xyz origin_rpy radius">
    <gazebo reference="${wheel_name}">
        <material>Gazebo/Grey</material>
    </gazebo>
    <!-- Caster wheel joint -->
    <joint name="${wheel_name}_joint" type="revolute">
      <parent link="${parent_link}"/>
      <child link="${wheel_name}"/>
      <origin xyz="${origin_xyz}" rpy="${origin_rpy}"/>
      <axis xyz="0 0 1"/>
      <limit effort="0.0" velocity="0.0" lower="-3.1416" upper="3.1416"/>
    </joint>

    <!-- Caster wheel link -->
    <link name="${wheel_name}">
      <inertial>
        <mass value="0.2"/>
        <origin xyz="0 0 0" rpy="0 0 0"/>
        <inertia ixx="0.001" iyy="0.001" izz="0.001" ixy="0" ixz="0" iyz="0"/>
      </inertial>
      <visual>
        <origin xyz="0 0 0" rpy="0 0 0"/>
        <geometry>
          <sphere radius="${radius}"/>
        </geometry>
        <material name="gray">
          <color rgba="0.8 0.8 0.8 1.0"/>
        </material>
      </visual>
      <collision>
        <origin xyz="0 0 0" rpy="0 0 0"/>
        <geometry>
          <sphere radius="${radius}"/>
        </geometry>
      </collision>
      <surface>
        <friction>
          <ode>
            <mu>0.0</mu>
            <mu2>0.0</mu2>
          </ode>
        </friction>
      </surface>
    </link>
  </xacro:macro>
</robot>
